# Exception Handling

Exception handling in Python is a mechanism to handle and manage runtime errors and exceptions that may occur during the execution of a program. Exceptions are events that disrupt the normal flow of the program and can be caused by various factors, such as invalid input, file errors, network issues, or logical errors. By using exception handling, you can catch and handle these exceptions gracefully, preventing the program from crashing and providing appropriate error messages. Here's an overview of exception handling in Python:

## Try-Except Block

- The primary construct for exception handling in Python is the `try-except` block.
- The `try` block contains the code that might raise an exception.
- The `except` block specifies the actions to be taken if a specific exception occurs within the `try` block.
- Multiple `except` blocks can be used to handle different types of exceptions.

Example:

```python
try:
    # code that may raise an exception
    result = 10 / 0  # division by zero
except ZeroDivisionError:
    # code to handle ZeroDivisionError
    print("Error: Division by zero!")
```

In the example above, the `try` block attempts to perform a division operation that may raise a `ZeroDivisionError`. If such an exception occurs, the program jumps to the corresponding `except` block and executes the code inside, which prints an error message.

## Handling Multiple Exceptions

- You can handle multiple exceptions by including multiple `except` blocks, each handling a specific exception.
- The exceptions can be specified individually or as a tuple.

Example:

```python
try:
    # code that may raise exceptions
    result = 10 / 0  # division by zero
    value = int("abc")  # invalid conversion
except ZeroDivisionError:
    # code to handle ZeroDivisionError
    print("Error: Division by zero!")
except ValueError:
    # code to handle ValueError
    print("Error: Invalid conversion!")
```

In the example above, the `try` block contains two operations that may raise exceptions: division by zero and invalid conversion. The corresponding `except` blocks handle each exception separately and provide specific error messages.

## Handling Generic Exceptions

- You can use a generic `except` block without specifying a particular exception to handle any unexpected exceptions that occur.
- However, it is generally recommended to handle specific exceptions whenever possible to provide more meaningful error messages.

Example:

```python
try:
    # code that may raise an exception
    result = 10 / 0  # division by zero
except Exception as e:
    # code to handle any exception
    print("An error occurred:", str(e))
```

In the example above, the `except` block without specifying a specific exception catches any exception that occurs. The `Exception` class is used to handle the exception, and the error message is printed.

## Finally Block

- The `finally` block can be used to specify cleanup actions that should always be executed, regardless of whether an exception occurred or not.
- The code inside the `finally` block is executed even if there is a matching `except` block or if no exception is raised.

Example:

```python
try:
    # code that may raise an exception
    result = 10 / 0  # division by zero
except ZeroDivisionError:
    # code to handle ZeroDivisionError
    print("Error: Division by zero!")
finally:
    # code to execute regardless of exceptions
    print("Cleanup actions...")
```

In the example above, the `finally` block is used to perform cleanup actions, such as closing files or releasing resources, regardless of whether an exception occurred or not.

## Raising Exceptions

- You can manually raise exceptions using the `raise` statement.
- This can be useful when you want to indicate an error condition or handle specific scenarios.

Example:

```python
def validate_age(age):
    if age < 0:
        raise ValueError("Age cannot be negative.")
    elif age > 120:
        raise ValueError("Invalid age.")
    else:
        print("Age is valid.")

try:
    validate_age(-5)
except ValueError as e:
    print("Invalid age:", str(e))
```

In the example above, the `validate_age()` function raises a `ValueError` if the given age is negative or exceeds 120. The `except` block handles the raised exception and prints an appropriate error message.

Exception handling allows you to gracefully handle runtime errors and exceptions in your Python programs. By using `try-except` blocks, you can catch and handle specific exceptions, perform cleanup actions with the `finally` block, and even raise your own exceptions when needed. Effective exception handling improves the stability and reliability of your programs and provides a way to handle error scenarios gracefully.
